Workbook

Sheet Cover Page
B3: National Cybersecurity Authority (NCA)
B5: Essential Cybersecurity Controls (ECC-2:2024)
B6: Compliance Assessment Tool
B9: Entity Name:
B10: Assessor Name:
B11: Assessment Date:
B12: Assessment Scope: | C12: Full ECC-2:2024 Compliance Assessment
B13: Framework Version: | C13: ECC-2:2024
B14: Domains: | C14: 4 Main Domains
B15: Subdomains: | C15: 28 Subdomains
B16: Total Controls: | C16: 108 Main Controls
B18: Status Legend
B19: Compliant | C19: Compliant | D19: Control is fully implemented
B20: Partially Compliant | C20: Partially Compliant | D20: Control is partially implemented
B21: Non-Compliant | C21: Non-Compliant | D21: Control is not implemented
B22: Not Applicable | C22: Not Applicable | D22: Control does not apply

Sheet Dashboard
B2: ECC-2:2024 Compliance Dashboard
B4: Overall Summary
B5: Metric | C5: Value
B6: Total Controls | C6: 108
B7: Assessed | C7: =COUNTIF(Assessment!F1:F143,"Compliant")+COUNTIF(Assessment!F1:F143,"Partially Compliant")+COUNTIF(Assessment!F1:F143,"Non-Compliant")+COUNTIF(Assessment!F1:F143,"Not Applicable") -> 0
B8: Compliant | C8: =COUNTIF(Assessment!F1:F143,"Compliant") -> 0
B9: Partially Compliant | C9: =COUNTIF(Assessment!F1:F143,"Partially Compliant") -> 0
B10: Non-Compliant | C10: =COUNTIF(Assessment!F1:F143,"Non-Compliant") -> 0
B11: Not Applicable | C11: =COUNTIF(Assessment!F1:F143,"Not Applicable") -> 0
B12: Compliance Rate | C12: =IF((COUNTIF(Assessment!F1:F143,"Compliant")+COUNTIF(Assessment!F1:F143,"Partially Compliant")+COUNTIF(Assessment!F1:F143,"Non-Compliant"))>0,COUNTIF(Assessment!F1:F143,"Compliant")/(COUNTIF(Assessment!F1:F143,"Compliant")+COUNTIF(Assessment!F1:F143,"Partially Compliant")+COUNTIF(Assessment!F1:F143,"Non-Compliant")),0) -> 0
B15: Status | C15: Count
B16: Compliant | C16: =C8 -> 0
B17: Partially Compliant | C17: =C9 -> 0
B18: Non-Compliant | C18: =C10 -> 0
B19: Not Applicable | C19: =C11 -> 0
B22: Domain Compliance Breakdown
B23: Domain | C23: Total | D23: Compliant | E23: Partial | F23: Non-Comp. | G23: N/A | H23: Compliance %
B24: Cybersecurity Governance | C24: 35 | D24: =COUNTIF(Assessment!F6:F49,"Compliant") -> 0 | E24: =COUNTIF(Assessment!F6:F49,"Partially Compliant") -> 0 | F24: =COUNTIF(Assessment!F6:F49,"Non-Compliant") -> 0 | G24: =COUNTIF(Assessment!F6:F49,"Not Applicable") -> 0 | H24: =IF((D24+E24+F24)>0,D24/(D24+E24+F24),0) -> 0
B25: Cybersecurity Defense | C25: 61 | D25: =COUNTIF(Assessment!F52:F126,"Compliant") -> 0 | E25: =COUNTIF(Assessment!F52:F126,"Partially Compliant") -> 0 | F25: =COUNTIF(Assessment!F52:F126,"Non-Compliant") -> 0 | G25: =COUNTIF(Assessment!F52:F126,"Not Applicable") -> 0 | H25: =IF((D25+E25+F25)>0,D25/(D25+E25+F25),0) -> 0
B26: Cybersecurity Resilience | C26: 4 | D26: =COUNTIF(Assessment!F129:F132,"Compliant") -> 0 | E26: =COUNTIF(Assessment!F129:F132,"Partially Compliant") -> 0 | F26: =COUNTIF(Assessment!F129:F132,"Non-Compliant") -> 0 | G26: =COUNTIF(Assessment!F129:F132,"Not Applicable") -> 0 | H26: =IF((D26+E26+F26)>0,D26/(D26+E26+F26),0) -> 0
B27: Third-Party & Cloud Cybersecurity | C27: 8 | D27: =COUNTIF(Assessment!F135:F143,"Compliant") -> 0 | E27: =COUNTIF(Assessment!F135:F143,"Partially Compliant") -> 0 | F27: =COUNTIF(Assessment!F135:F143,"Non-Compliant") -> 0 | G27: =COUNTIF(Assessment!F135:F143,"Not Applicable") -> 0 | H27: =IF((D27+E27+F27)>0,D27/(D27+E27+F27),0) -> 0

Sheet Assessment
A1: NCA ECC-2:2024 — Compliance Assessment Worksheet
A2: Select status from dropdown: Compliant, Partially Compliant, Non-Compliant, or Not Applicable. Use Domain column filter to focus on specific domains.
A3: Domain | B3: Control ID | C3: Subdomain | D3: Control | E3: Detailed Description (ECC Framework) | F3: Status | G3: Evidence / Artifacts | H3: Assessment Notes | I3: Remediation Action
A4: DOMAIN 1: CYBERSECURITY GOVERNANCE
A5: 1-1 Cybersecurity Strategy — Ensure action plans, objectives, initiatives, and projects contribute to compliance with relevant legislative and regulatory requirements.
A6: Domain 1: Cybersecurity Governance | B6: 1-1-1 | C6: 1-1 Cybersecurity Strategy | D6: Cybersecurity strategy identified, documented, approved, and supported by entity head. | E6: The cybersecurity strategy of the entity shall be identified, documented, and approved, and it shall be supported by the head of the entity or his/her delegate (Authorized Official). The strategy goals shall be in line with the relevant legislative and regulatory requirements.
A7: Domain 1: Cybersecurity Governance | B7: 1-1-2 | C7: 1-1 Cybersecurity Strategy | D7: Action plan to apply the cybersecurity strategy is executed. | E7: The entity shall execute an action plan to apply the cybersecurity strategy.
A8: Domain 1: Cybersecurity Governance | B8: 1-1-3 | C8: 1-1 Cybersecurity Strategy | D8: Cybersecurity strategy reviewed at planned intervals. | E8: The cybersecurity strategy shall be reviewed at planned intervals (or in case of changes to the relevant legislative and regulatory requirements).
A9: 1-2 Cybersecurity Management — Ensure the Authorized Official complies with and supports implementation and management of cybersecurity programs.
A10: Domain 1: Cybersecurity Governance | B10: 1-2-1 | C10: 1-2 Cybersecurity Management | D10: Independent cybersecurity department established, separate from IT. | E10: A department for cybersecurity shall be established within the entity. This department shall be independent from the IT and Communications Department (as per High Order No. 37140).
A11: Domain 1: Cybersecurity Governance | B11: 1-2-2 | C11: 1-2 Cybersecurity Management | D11: All cybersecurity positions filled with qualified Saudi professionals. | E11: All cybersecurity positions shall be filled out with full-time and qualified Saudi cybersecurity professionals.
A12: Domain 1: Cybersecurity Governance | B12: 1-2-3 | C12: 1-2 Cybersecurity Management | D12: Cybersecurity supervisory committee established. | E12: A cybersecurity supervisory committee shall be established pursuant to the instruction of the entity's Authorized Official to ensure compliance with, support for, and monitoring of the implementation of cybersecurity programs and regulations.
A13: 1-3 Cybersecurity Policies and Procedures — Ensure cybersecurity requirements and compliance are documented and communicated.
A14: Domain 1: Cybersecurity Governance | B14: 1-3-1 | C14: 1-3 Cybersecurity Policies and Procedures | D14: Policies and procedures documented, approved, and communicated. | E14: The cybersecurity department shall identify and document cybersecurity policies and procedures, including controls and requirements, have them approved by the Authorized Official, and communicate them to relevant personnel and parties.
A15: Domain 1: Cybersecurity Governance | B15: 1-3-2 | C15: 1-3 Cybersecurity Policies and Procedures | D15: Policies and procedures implemented at the entity. | E15: The cybersecurity department shall ensure that the cybersecurity policies and procedures, including relevant controls and requirements, are implemented at the entity.
A16: Domain 1: Cybersecurity Governance | B16: 1-3-3 | C16: 1-3 Cybersecurity Policies and Procedures | D16: Policies supported by technical security standards. | E16: The cybersecurity policies and procedures shall be supported by technical security standards (e.g. technical security standards for firewall, databases, operating systems, etc.).
A17: Domain 1: Cybersecurity Governance | B17: 1-3-4 | C17: 1-3 Cybersecurity Policies and Procedures | D17: Policies reviewed and updated at planned intervals. | E17: The cybersecurity policies and procedures shall be reviewed and updated at planned intervals (or in case of changes to the relevant legislative and regulatory requirements and standards). Changes shall be documented and approved.
A18: 1-4 Cybersecurity Roles and Responsibilities — Ensure roles and responsibilities are clearly defined for all parties implementing cybersecurity controls.
A19: Domain 1: Cybersecurity Governance | B19: 1-4-1 | C19: 1-4 Cybersecurity Roles and Responsibilities | D19: Governance structure, roles, and responsibilities documented and assigned. | E19: The Authorized Official shall identify, document, and approve the governance organizational structure, roles, and responsibilities of the entity's cybersecurity, and assign the persons concerned therewith.
A20: Domain 1: Cybersecurity Governance | B20: 1-4-2 | C20: 1-4 Cybersecurity Roles and Responsibilities | D20: Roles and responsibilities reviewed at planned intervals. | E20: The cybersecurity roles and responsibilities within the entity shall be reviewed and updated at planned intervals (or in case of changes to the relevant legislative and regulatory requirements).
A21: 1-5 Cybersecurity Risk Management — Manage cybersecurity risks methodologically to protect information and technology assets.
A22: Domain 1: Cybersecurity Governance | B22: 1-5-1 | C22: 1-5 Cybersecurity Risk Management | D22: Risk management methodology documented and approved. | E22: The cybersecurity department shall identify, document, and approve the cybersecurity risk management methodology and procedures, in accordance with confidentiality, integrity and availability of information and technology assets.
A23: Domain 1: Cybersecurity Governance | B23: 1-5-2 | C23: 1-5 Cybersecurity Risk Management | D23: Risk management methodology implemented. | E23: The cybersecurity department shall implement the cybersecurity risk management methodology and procedures within the entity.
A24: Domain 1: Cybersecurity Governance | B24: 1-5-3 | C24: 1-5 Cybersecurity Risk Management | D24: Risk assessments conducted at key stages. | E24: Risk assessment procedures shall be implemented at: (1) early stage of technology projects, (2) before major changes to technology infrastructure, (3) during planning to obtain third party services, (4) during planning and before release of new technology services and products.
A25: Domain 1: Cybersecurity Governance | B25: 1-5-4 | C25: 1-5 Cybersecurity Risk Management | D25: Risk management methodology reviewed and updated. | E25: The methodology and procedures shall be reviewed and updated at planned intervals (or in case of changes to legislative/regulatory requirements). Changes shall be documented and approved.
A26: 1-6 Cybersecurity in IT Project Management — Ensure cybersecurity requirements are included in project management methodology to protect assets.
A27: Domain 1: Cybersecurity Governance | B27: 1-6-1 | C27: 1-6 Cybersecurity in IT Project Management | D27: Cybersecurity included in project and change management. | E27: Cybersecurity requirements shall be included in the project management methodology and procedures and in information and technology asset change management.
A28: Domain 1: Cybersecurity Governance | B28: 1-6-2 | C28: 1-6 Cybersecurity in IT Project Management | D28: Vulnerability assessment and secure config review before launch. | E28: Requirements shall include: (1) vulnerability assessment and remediation, (2) reviewing secure configuration, hardening, and update packages before launching projects and changes.
A29: Domain 1: Cybersecurity Governance | B29: 1-6-3 | C29: 1-6 Cybersecurity in IT Project Management | D29: Secure software development requirements. | E29: Software development requirements shall include: (1) secure coding standards, (2) trusted and licensed sources for development tools and libraries, (3) compliance testing against cybersecurity requirements, (4) secure integration between applications, (5) secure configuration review before launching software products.
A30: Domain 1: Cybersecurity Governance | B30: 1-6-4 | C30: 1-6 Cybersecurity in IT Project Management | D30: Project management cybersecurity requirements reviewed. | E30: The cybersecurity requirements for project management within the entity shall be periodically reviewed.
A31: 1-7 Compliance with Standards, Laws & Regulations — Ensure the entity's cybersecurity program complies with relevant legislative and regulatory requirements.
A32: Domain 1: Cybersecurity Governance | B32: 1-7-1 | C32: 1-7 Compliance with Standards, Laws & Regulations | D32: Comply with international agreements including cybersecurity. | E32: If there are nationally approved international agreements or commitments that include cybersecurity requirements, the entity shall identify and comply with these requirements.
A33: 1-8 Periodical Review and Audit — Ensure cybersecurity controls are implemented and applicable in accordance with policies and requirements.
A34: Domain 1: Cybersecurity Governance | B34: 1-8-1 | C34: 1-8 Periodical Review and Audit | D34: Cybersecurity department periodically reviews controls. | E34: The cybersecurity department of the entity shall periodically review the implementation of cybersecurity controls by the entity.
A35: Domain 1: Cybersecurity Governance | B35: 1-8-2 | C35: 1-8 Periodical Review and Audit | D35: Independent audit of controls (GAAS compliant). | E35: The implementation of cybersecurity controls shall be reviewed and audited by parties other than the cybersecurity department, conducted independently while considering conflict of interest, as per Generally Accepted Auditing Standards (GAAS).
A36: Domain 1: Cybersecurity Governance | B36: 1-8-3 | C36: 1-8 Periodical Review and Audit | D36: Audit results documented and presented. | E36: The results of cybersecurity audits and reviews shall be documented and presented to the cybersecurity supervisory committee and the Authorized Official.
A37: 1-9 Cybersecurity in Human Resources — Manage cybersecurity risks for personnel prior to, during, and upon end/termination of employment.
A38: Domain 1: Cybersecurity Governance | B38: 1-9-1 | C38: 1-9 Cybersecurity in Human Resources | D38: Personnel requirements identified and approved. | E38: Cybersecurity requirements for personnel of the entity shall be identified, documented, and approved prior to, during, and upon the end or termination of their employment.
A39: Domain 1: Cybersecurity Governance | B39: 1-9-2 | C39: 1-9 Cybersecurity in Human Resources | D39: Personnel cybersecurity requirements implemented. | E39: Cybersecurity requirements for personnel of the entity shall be implemented.
A40: Domain 1: Cybersecurity Governance | B40: 1-9-3 | C40: 1-9 Cybersecurity in Human Resources | D40: Pre-employment screening and contract clauses. | E40: Pre-employment requirements include: (1) incorporating cybersecurity responsibilities and non-disclosure clauses in employment contracts, (2) conducting screening or vetting for personnel in cybersecurity and critical positions.
...

Sheet Gap Analysis
A1: NCA ECC-2:2024 — Gap Analysis Report (Auto-Populated)
A2: This sheet auto-populates from the Assessment sheet. Controls marked Non-Compliant or Partially Compliant appear below with their details.
A3: # | B3: Control ID | C3: Subdomain | D3: Control | E3: Detailed Description | F3: Status | G3: Evidence Gap / Finding | H3: Remediation Plan | I3: Target Date
A4: =IF(OR(Assessment!F6="Non-Compliant",Assessment!F6="Partially Compliant"),1,"") | B4: =IF(OR(Assessment!F6="Non-Compliant",Assessment!F6="Partially Compliant"),Assessment!B6,"") | C4: =IF(OR(Assessment!F6="Non-Compliant",Assessment!F6="Partially Compliant"),Assessment!C6,"") | D4: =IF(OR(Assessment!F6="Non-Compliant",Assessment!F6="Partially Compliant"),Assessment!D6,"") | E4: =IF(OR(Assessment!F6="Non-Compliant",Assessment!F6="Partially Compliant"),Assessment!E6,"") | F4: =IF(OR(Assessment!F6="Non-Compliant",Assessment!F6="Partially Compliant"),Assessment!F6,"")
A5: =IF(OR(Assessment!F7="Non-Compliant",Assessment!F7="Partially Compliant"),2,"") | B5: =IF(OR(Assessment!F7="Non-Compliant",Assessment!F7="Partially Compliant"),Assessment!B7,"") | C5: =IF(OR(Assessment!F7="Non-Compliant",Assessment!F7="Partially Compliant"),Assessment!C7,"") | D5: =IF(OR(Assessment!F7="Non-Compliant",Assessment!F7="Partially Compliant"),Assessment!D7,"") | E5: =IF(OR(Assessment!F7="Non-Compliant",Assessment!F7="Partially Compliant"),Assessment!E7,"") | F5: =IF(OR(Assessment!F7="Non-Compliant",Assessment!F7="Partially Compliant"),Assessment!F7,"")
A6: =IF(OR(Assessment!F8="Non-Compliant",Assessment!F8="Partially Compliant"),3,"") | B6: =IF(OR(Assessment!F8="Non-Compliant",Assessment!F8="Partially Compliant"),Assessment!B8,"") | C6: =IF(OR(Assessment!F8="Non-Compliant",Assessment!F8="Partially Compliant"),Assessment!C8,"") | D6: =IF(OR(Assessment!F8="Non-Compliant",Assessment!F8="Partially Compliant"),Assessment!D8,"") | E6: =IF(OR(Assessment!F8="Non-Compliant",Assessment!F8="Partially Compliant"),Assessment!E8,"") | F6: =IF(OR(Assessment!F8="Non-Compliant",Assessment!F8="Partially Compliant"),Assessment!F8,"")
A7: =IF(OR(Assessment!F10="Non-Compliant",Assessment!F10="Partially Compliant"),4,"") | B7: =IF(OR(Assessment!F10="Non-Compliant",Assessment!F10="Partially Compliant"),Assessment!B10,"") | C7: =IF(OR(Assessment!F10="Non-Compliant",Assessment!F10="Partially Compliant"),Assessment!C10,"") | D7: =IF(OR(Assessment!F10="Non-Compliant",Assessment!F10="Partially Compliant"),Assessment!D10,"") | E7: =IF(OR(Assessment!F10="Non-Compliant",Assessment!F10="Partially Compliant"),Assessment!E10,"") | F7: =IF(OR(Assessment!F10="Non-Compliant",Assessment!F10="Partially Compliant"),Assessment!F10,"")
A8: =IF(OR(Assessment!F11="Non-Compliant",Assessment!F11="Partially Compliant"),5,"") | B8: =IF(OR(Assessment!F11="Non-Compliant",Assessment!F11="Partially Compliant"),Assessment!B11,"") | C8: =IF(OR(Assessment!F11="Non-Compliant",Assessment!F11="Partially Compliant"),Assessment!C11,"") | D8: =IF(OR(Assessment!F11="Non-Compliant",Assessment!F11="Partially Compliant"),Assessment!D11,"") | E8: =IF(OR(Assessment!F11="Non-Compliant",Assessment!F11="Partially Compliant"),Assessment!E11,"") | F8: =IF(OR(Assessment!F11="Non-Compliant",Assessment!F11="Partially Compliant"),Assessment!F11,"")
A9: =IF(OR(Assessment!F12="Non-Compliant",Assessment!F12="Partially Compliant"),6,"") | B9: =IF(OR(Assessment!F12="Non-Compliant",Assessment!F12="Partially Compliant"),Assessment!B12,"") | C9: =IF(OR(Assessment!F12="Non-Compliant",Assessment!F12="Partially Compliant"),Assessment!C12,"") | D9: =IF(OR(Assessment!F12="Non-Compliant",Assessment!F12="Partially Compliant"),Assessment!D12,"") | E9: =IF(OR(Assessment!F12="Non-Compliant",Assessment!F12="Partially Compliant"),Assessment!E12,"") | F9: =IF(OR(Assessment!F12="Non-Compliant",Assessment!F12="Partially Compliant"),Assessment!F12,"")
A10: =IF(OR(Assessment!F14="Non-Compliant",Assessment!F14="Partially Compliant"),7,"") | B10: =IF(OR(Assessment!F14="Non-Compliant",Assessment!F14="Partially Compliant"),Assessment!B14,"") | C10: =IF(OR(Assessment!F14="Non-Compliant",Assessment!F14="Partially Compliant"),Assessment!C14,"") | D10: =IF(OR(Assessment!F14="Non-Compliant",Assessment!F14="Partially Compliant"),Assessment!D14,"") | E10: =IF(OR(Assessment!F14="Non-Compliant",Assessment!F14="Partially Compliant"),Assessment!E14,"") | F10: =IF(OR(Assessment!F14="Non-Compliant",Assessment!F14="Partially Compliant"),Assessment!F14,"")
A11: =IF(OR(Assessment!F15="Non-Compliant",Assessment!F15="Partially Compliant"),8,"") | B11: =IF(OR(Assessment!F15="Non-Compliant",Assessment!F15="Partially Compliant"),Assessment!B15,"") | C11: =IF(OR(Assessment!F15="Non-Compliant",Assessment!F15="Partially Compliant"),Assessment!C15,"") | D11: =IF(OR(Assessment!F15="Non-Compliant",Assessment!F15="Partially Compliant"),Assessment!D15,"") | E11: =IF(OR(Assessment!F15="Non-Compliant",Assessment!F15="Partially Compliant"),Assessment!E15,"") | F11: =IF(OR(Assessment!F15="Non-Compliant",Assessment!F15="Partially Compliant"),Assessment!F15,"")
A12: =IF(OR(Assessment!F16="Non-Compliant",Assessment!F16="Partially Compliant"),9,"") | B12: =IF(OR(Assessment!F16="Non-Compliant",Assessment!F16="Partially Compliant"),Assessment!B16,"") | C12: =IF(OR(Assessment!F16="Non-Compliant",Assessment!F16="Partially Compliant"),Assessment!C16,"") | D12: =IF(OR(Assessment!F16="Non-Compliant",Assessment!F16="Partially Compliant"),Assessment!D16,"") | E12: =IF(OR(Assessment!F16="Non-Compliant",Assessment!F16="Partially Compliant"),Assessment!E16,"") | F12: =IF(OR(Assessment!F16="Non-Compliant",Assessment!F16="Partially Compliant"),Assessment!F16,"")
A13: =IF(OR(Assessment!F17="Non-Compliant",Assessment!F17="Partially Compliant"),10,"") | B13: =IF(OR(Assessment!F17="Non-Compliant",Assessment!F17="Partially Compliant"),Assessment!B17,"") | C13: =IF(OR(Assessment!F17="Non-Compliant",Assessment!F17="Partially Compliant"),Assessment!C17,"") | D13: =IF(OR(Assessment!F17="Non-Compliant",Assessment!F17="Partially Compliant"),Assessment!D17,"") | E13: =IF(OR(Assessment!F17="Non-Compliant",Assessment!F17="Partially Compliant"),Assessment!E17,"") | F13: =IF(OR(Assessment!F17="Non-Compliant",Assessment!F17="Partially Compliant"),Assessment!F17,"")
A14: =IF(OR(Assessment!F19="Non-Compliant",Assessment!F19="Partially Compliant"),11,"") | B14: =IF(OR(Assessment!F19="Non-Compliant",Assessment!F19="Partially Compliant"),Assessment!B19,"") | C14: =IF(OR(Assessment!F19="Non-Compliant",Assessment!F19="Partially Compliant"),Assessment!C19,"") | D14: =IF(OR(Assessment!F19="Non-Compliant",Assessment!F19="Partially Compliant"),Assessment!D19,"") | E14: =IF(OR(Assessment!F19="Non-Compliant",Assessment!F19="Partially Compliant"),Assessment!E19,"") | F14: =IF(OR(Assessment!F19="Non-Compliant",Assessment!F19="Partially Compliant"),Assessment!F19,"")
A15: =IF(OR(Assessment!F20="Non-Compliant",Assessment!F20="Partially Compliant"),12,"") | B15: =IF(OR(Assessment!F20="Non-Compliant",Assessment!F20="Partially Compliant"),Assessment!B20,"") | C15: =IF(OR(Assessment!F20="Non-Compliant",Assessment!F20="Partially Compliant"),Assessment!C20,"") | D15: =IF(OR(Assessment!F20="Non-Compliant",Assessment!F20="Partially Compliant"),Assessment!D20,"") | E15: =IF(OR(Assessment!F20="Non-Compliant",Assessment!F20="Partially Compliant"),Assessment!E20,"") | F15: =IF(OR(Assessment!F20="Non-Compliant",Assessment!F20="Partially Compliant"),Assessment!F20,"")
A16: =IF(OR(Assessment!F22="Non-Compliant",Assessment!F22="Partially Compliant"),13,"") | B16: =IF(OR(Assessment!F22="Non-Compliant",Assessment!F22="Partially Compliant"),Assessment!B22,"") | C16: =IF(OR(Assessment!F22="Non-Compliant",Assessment!F22="Partially Compliant"),Assessment!C22,"") | D16: =IF(OR(Assessment!F22="Non-Compliant",Assessment!F22="Partially Compliant"),Assessment!D22,"") | E16: =IF(OR(Assessment!F22="Non-Compliant",Assessment!F22="Partially Compliant"),Assessment!E22,"") | F16: =IF(OR(Assessment!F22="Non-Compliant",Assessment!F22="Partially Compliant"),Assessment!F22,"")
A17: =IF(OR(Assessment!F23="Non-Compliant",Assessment!F23="Partially Compliant"),14,"") | B17: =IF(OR(Assessment!F23="Non-Compliant",Assessment!F23="Partially Compliant"),Assessment!B23,"") | C17: =IF(OR(Assessment!F23="Non-Compliant",Assessment!F23="Partially Compliant"),Assessment!C23,"") | D17: =IF(OR(Assessment!F23="Non-Compliant",Assessment!F23="Partially Compliant"),Assessment!D23,"") | E17: =IF(OR(Assessment!F23="Non-Compliant",Assessment!F23="Partially Compliant"),Assessment!E23,"") | F17: =IF(OR(Assessment!F23="Non-Compliant",Assessment!F23="Partially Compliant"),Assessment!F23,"")
A18: =IF(OR(Assessment!F24="Non-Compliant",Assessment!F24="Partially Compliant"),15,"") | B18: =IF(OR(Assessment!F24="Non-Compliant",Assessment!F24="Partially Compliant"),Assessment!B24,"") | C18: =IF(OR(Assessment!F24="Non-Compliant",Assessment!F24="Partially Compliant"),Assessment!C24,"") | D18: =IF(OR(Assessment!F24="Non-Compliant",Assessment!F24="Partially Compliant"),Assessment!D24,"") | E18: =IF(OR(Assessment!F24="Non-Compliant",Assessment!F24="Partially Compliant"),Assessment!E24,"") | F18: =IF(OR(Assessment!F24="Non-Compliant",Assessment!F24="Partially Compliant"),Assessment!F24,"")
A19: =IF(OR(Assessment!F25="Non-Compliant",Assessment!F25="Partially Compliant"),16,"") | B19: =IF(OR(Assessment!F25="Non-Compliant",Assessment!F25="Partially Compliant"),Assessment!B25,"") | C19: =IF(OR(Assessment!F25="Non-Compliant",Assessment!F25="Partially Compliant"),Assessment!C25,"") | D19: =IF(OR(Assessment!F25="Non-Compliant",Assessment!F25="Partially Compliant"),Assessment!D25,"") | E19: =IF(OR(Assessment!F25="Non-Compliant",Assessment!F25="Partially Compliant"),Assessment!E25,"") | F19: =IF(OR(Assessment!F25="Non-Compliant",Assessment!F25="Partially Compliant"),Assessment!F25,"")
A20: =IF(OR(Assessment!F27="Non-Compliant",Assessment!F27="Partially Compliant"),17,"") | B20: =IF(OR(Assessment!F27="Non-Compliant",Assessment!F27="Partially Compliant"),Assessment!B27,"") | C20: =IF(OR(Assessment!F27="Non-Compliant",Assessment!F27="Partially Compliant"),Assessment!C27,"") | D20: =IF(OR(Assessment!F27="Non-Compliant",Assessment!F27="Partially Compliant"),Assessment!D27,"") | E20: =IF(OR(Assessment!F27="Non-Compliant",Assessment!F27="Partially Compliant"),Assessment!E27,"") | F20: =IF(OR(Assessment!F27="Non-Compliant",Assessment!F27="Partially Compliant"),Assessment!F27,"")
A21: =IF(OR(Assessment!F28="Non-Compliant",Assessment!F28="Partially Compliant"),18,"") | B21: =IF(OR(Assessment!F28="Non-Compliant",Assessment!F28="Partially Compliant"),Assessment!B28,"") | C21: =IF(OR(Assessment!F28="Non-Compliant",Assessment!F28="Partially Compliant"),Assessment!C28,"") | D21: =IF(OR(Assessment!F28="Non-Compliant",Assessment!F28="Partially Compliant"),Assessment!D28,"") | E21: =IF(OR(Assessment!F28="Non-Compliant",Assessment!F28="Partially Compliant"),Assessment!E28,"") | F21: =IF(OR(Assessment!F28="Non-Compliant",Assessment!F28="Partially Compliant"),Assessment!F28,"")
A22: =IF(OR(Assessment!F29="Non-Compliant",Assessment!F29="Partially Compliant"),19,"") | B22: =IF(OR(Assessment!F29="Non-Compliant",Assessment!F29="Partially Compliant"),Assessment!B29,"") | C22: =IF(OR(Assessment!F29="Non-Compliant",Assessment!F29="Partially Compliant"),Assessment!C29,"") | D22: =IF(OR(Assessment!F29="Non-Compliant",Assessment!F29="Partially Compliant"),Assessment!D29,"") | E22: =IF(OR(Assessment!F29="Non-Compliant",Assessment!F29="Partially Compliant"),Assessment!E29,"") | F22: =IF(OR(Assessment!F29="Non-Compliant",Assessment!F29="Partially Compliant"),Assessment!F29,"")
A23: =IF(OR(Assessment!F30="Non-Compliant",Assessment!F30="Partially Compliant"),20,"") | B23: =IF(OR(Assessment!F30="Non-Compliant",Assessment!F30="Partially Compliant"),Assessment!B30,"") | C23: =IF(OR(Assessment!F30="Non-Compliant",Assessment!F30="Partially Compliant"),Assessment!C30,"") | D23: =IF(OR(Assessment!F30="Non-Compliant",Assessment!F30="Partially Compliant"),Assessment!D30,"") | E23: =IF(OR(Assessment!F30="Non-Compliant",Assessment!F30="Partially Compliant"),Assessment!E30,"") | F23: =IF(OR(Assessment!F30="Non-Compliant",Assessment!F30="Partially Compliant"),Assessment!F30,"")
A24: =IF(OR(Assessment!F32="Non-Compliant",Assessment!F32="Partially Compliant"),21,"") | B24: =IF(OR(Assessment!F32="Non-Compliant",Assessment!F32="Partially Compliant"),Assessment!B32,"") | C24: =IF(OR(Assessment!F32="Non-Compliant",Assessment!F32="Partially Compliant"),Assessment!C32,"") | D24: =IF(OR(Assessment!F32="Non-Compliant",Assessment!F32="Partially Compliant"),Assessment!D32,"") | E24: =IF(OR(Assessment!F32="Non-Compliant",Assessment!F32="Partially Compliant"),Assessment!E32,"") | F24: =IF(OR(Assessment!F32="Non-Compliant",Assessment!F32="Partially Compliant"),Assessment!F32,"")
A25: =IF(OR(Assessment!F34="Non-Compliant",Assessment!F34="Partially Compliant"),22,"") | B25: =IF(OR(Assessment!F34="Non-Compliant",Assessment!F34="Partially Compliant"),Assessment!B34,"") | C25: =IF(OR(Assessment!F34="Non-Compliant",Assessment!F34="Partially Compliant"),Assessment!C34,"") | D25: =IF(OR(Assessment!F34="Non-Compliant",Assessment!F34="Partially Compliant"),Assessment!D34,"") | E25: =IF(OR(Assessment!F34="Non-Compliant",Assessment!F34="Partially Compliant"),Assessment!E34,"") | F25: =IF(OR(Assessment!F34="Non-Compliant",Assessment!F34="Partially Compliant"),Assessment!F34,"")
A26: =IF(OR(Assessment!F35="Non-Compliant",Assessment!F35="Partially Compliant"),23,"") | B26: =IF(OR(Assessment!F35="Non-Compliant",Assessment!F35="Partially Compliant"),Assessment!B35,"") | C26: =IF(OR(Assessment!F35="Non-Compliant",Assessment!F35="Partially Compliant"),Assessment!C35,"") | D26: =IF(OR(Assessment!F35="Non-Compliant",Assessment!F35="Partially Compliant"),Assessment!D35,"") | E26: =IF(OR(Assessment!F35="Non-Compliant",Assessment!F35="Partially Compliant"),Assessment!E35,"") | F26: =IF(OR(Assessment!F35="Non-Compliant",Assessment!F35="Partially Compliant"),Assessment!F35,"")
A27: =IF(OR(Assessment!F36="Non-Compliant",Assessment!F36="Partially Compliant"),24,"") | B27: =IF(OR(Assessment!F36="Non-Compliant",Assessment!F36="Partially Compliant"),Assessment!B36,"") | C27: =IF(OR(Assessment!F36="Non-Compliant",Assessment!F36="Partially Compliant"),Assessment!C36,"") | D27: =IF(OR(Assessment!F36="Non-Compliant",Assessment!F36="Partially Compliant"),Assessment!D36,"") | E27: =IF(OR(Assessment!F36="Non-Compliant",Assessment!F36="Partially Compliant"),Assessment!E36,"") | F27: =IF(OR(Assessment!F36="Non-Compliant",Assessment!F36="Partially Compliant"),Assessment!F36,"")
A28: =IF(OR(Assessment!F38="Non-Compliant",Assessment!F38="Partially Compliant"),25,"") | B28: =IF(OR(Assessment!F38="Non-Compliant",Assessment!F38="Partially Compliant"),Assessment!B38,"") | C28: =IF(OR(Assessment!F38="Non-Compliant",Assessment!F38="Partially Compliant"),Assessment!C38,"") | D28: =IF(OR(Assessment!F38="Non-Compliant",Assessment!F38="Partially Compliant"),Assessment!D38,"") | E28: =IF(OR(Assessment!F38="Non-Compliant",Assessment!F38="Partially Compliant"),Assessment!E38,"") | F28: =IF(OR(Assessment!F38="Non-Compliant",Assessment!F38="Partially Compliant"),Assessment!F38,"")
A29: =IF(OR(Assessment!F39="Non-Compliant",Assessment!F39="Partially Compliant"),26,"") | B29: =IF(OR(Assessment!F39="Non-Compliant",Assessment!F39="Partially Compliant"),Assessment!B39,"") | C29: =IF(OR(Assessment!F39="Non-Compliant",Assessment!F39="Partially Compliant"),Assessment!C39,"") | D29: =IF(OR(Assessment!F39="Non-Compliant",Assessment!F39="Partially Compliant"),Assessment!D39,"") | E29: =IF(OR(Assessment!F39="Non-Compliant",Assessment!F39="Partially Compliant"),Assessment!E39,"") | F29: =IF(OR(Assessment!F39="Non-Compliant",Assessment!F39="Partially Compliant"),Assessment!F39,"")
A30: =IF(OR(Assessment!F40="Non-Compliant",Assessment!F40="Partially Compliant"),27,"") | B30: =IF(OR(Assessment!F40="Non-Compliant",Assessment!F40="Partially Compliant"),Assessment!B40,"") | C30: =IF(OR(Assessment!F40="Non-Compliant",Assessment!F40="Partially Compliant"),Assessment!C40,"") | D30: =IF(OR(Assessment!F40="Non-Compliant",Assessment!F40="Partially Compliant"),Assessment!D40,"") | E30: =IF(OR(Assessment!F40="Non-Compliant",Assessment!F40="Partially Compliant"),Assessment!E40,"") | F30: =IF(OR(Assessment!F40="Non-Compliant",Assessment!F40="Partially Compliant"),Assessment!F40,"")
A31: =IF(OR(Assessment!F41="Non-Compliant",Assessment!F41="Partially Compliant"),28,"") | B31: =IF(OR(Assessment!F41="Non-Compliant",Assessment!F41="Partially Compliant"),Assessment!B41,"") | C31: =IF(OR(Assessment!F41="Non-Compliant",Assessment!F41="Partially Compliant"),Assessment!C41,"") | D31: =IF(OR(Assessment!F41="Non-Compliant",Assessment!F41="Partially Compliant"),Assessment!D41,"") | E31: =IF(OR(Assessment!F41="Non-Compliant",Assessment!F41="Partially Compliant"),Assessment!E41,"") | F31: =IF(OR(Assessment!F41="Non-Compliant",Assessment!F41="Partially Compliant"),Assessment!F41,"")
A32: =IF(OR(Assessment!F42="Non-Compliant",Assessment!F42="Partially Compliant"),29,"") | B32: =IF(OR(Assessment!F42="Non-Compliant",Assessment!F42="Partially Compliant"),Assessment!B42,"") | C32: =IF(OR(Assessment!F42="Non-Compliant",Assessment!F42="Partially Compliant"),Assessment!C42,"") | D32: =IF(OR(Assessment!F42="Non-Compliant",Assessment!F42="Partially Compliant"),Assessment!D42,"") | E32: =IF(OR(Assessment!F42="Non-Compliant",Assessment!F42="Partially Compliant"),Assessment!E42,"") | F32: =IF(OR(Assessment!F42="Non-Compliant",Assessment!F42="Partially Compliant"),Assessment!F42,"")
A33: =IF(OR(Assessment!F43="Non-Compliant",Assessment!F43="Partially Compliant"),30,"") | B33: =IF(OR(Assessment!F43="Non-Compliant",Assessment!F43="Partially Compliant"),Assessment!B43,"") | C33: =IF(OR(Assessment!F43="Non-Compliant",Assessment!F43="Partially Compliant"),Assessment!C43,"") | D33: =IF(OR(Assessment!F43="Non-Compliant",Assessment!F43="Partially Compliant"),Assessment!D43,"") | E33: =IF(OR(Assessment!F43="Non-Compliant",Assessment!F43="Partially Compliant"),Assessment!E43,"") | F33: =IF(OR(Assessment!F43="Non-Compliant",Assessment!F43="Partially Compliant"),Assessment!F43,"")
A34: =IF(OR(Assessment!F45="Non-Compliant",Assessment!F45="Partially Compliant"),31,"") | B34: =IF(OR(Assessment!F45="Non-Compliant",Assessment!F45="Partially Compliant"),Assessment!B45,"") | C34: =IF(OR(Assessment!F45="Non-Compliant",Assessment!F45="Partially Compliant"),Assessment!C45,"") | D34: =IF(OR(Assessment!F45="Non-Compliant",Assessment!F45="Partially Compliant"),Assessment!D45,"") | E34: =IF(OR(Assessment!F45="Non-Compliant",Assessment!F45="Partially Compliant"),Assessment!E45,"") | F34: =IF(OR(Assessment!F45="Non-Compliant",Assessment!F45="Partially Compliant"),Assessment!F45,"")
A35: =IF(OR(Assessment!F46="Non-Compliant",Assessment!F46="Partially Compliant"),32,"") | B35: =IF(OR(Assessment!F46="Non-Compliant",Assessment!F46="Partially Compliant"),Assessment!B46,"") | C35: =IF(OR(Assessment!F46="Non-Compliant",Assessment!F46="Partially Compliant"),Assessment!C46,"") | D35: =IF(OR(Assessment!F46="Non-Compliant",Assessment!F46="Partially Compliant"),Assessment!D46,"") | E35: =IF(OR(Assessment!F46="Non-Compliant",Assessment!F46="Partially Compliant"),Assessment!E46,"") | F35: =IF(OR(Assessment!F46="Non-Compliant",Assessment!F46="Partially Compliant"),Assessment!F46,"")
A36: =IF(OR(Assessment!F47="Non-Compliant",Assessment!F47="Partially Compliant"),33,"") | B36: =IF(OR(Assessment!F47="Non-Compliant",Assessment!F47="Partially Compliant"),Assessment!B47,"") | C36: =IF(OR(Assessment!F47="Non-Compliant",Assessment!F47="Partially Compliant"),Assessment!C47,"") | D36: =IF(OR(Assessment!F47="Non-Compliant",Assessment!F47="Partially Compliant"),Assessment!D47,"") | E36: =IF(OR(Assessment!F47="Non-Compliant",Assessment!F47="Partially Compliant"),Assessment!E47,"") | F36: =IF(OR(Assessment!F47="Non-Compliant",Assessment!F47="Partially Compliant"),Assessment!F47,"")
A37: =IF(OR(Assessment!F48="Non-Compliant",Assessment!F48="Partially Compliant"),34,"") | B37: =IF(OR(Assessment!F48="Non-Compliant",Assessment!F48="Partially Compliant"),Assessment!B48,"") | C37: =IF(OR(Assessment!F48="Non-Compliant",Assessment!F48="Partially Compliant"),Assessment!C48,"") | D37: =IF(OR(Assessment!F48="Non-Compliant",Assessment!F48="Partially Compliant"),Assessment!D48,"") | E37: =IF(OR(Assessment!F48="Non-Compliant",Assessment!F48="Partially Compliant"),Assessment!E48,"") | F37: =IF(OR(Assessment!F48="Non-Compliant",Assessment!F48="Partially Compliant"),Assessment!F48,"")
A38: =IF(OR(Assessment!F49="Non-Compliant",Assessment!F49="Partially Compliant"),35,"") | B38: =IF(OR(Assessment!F49="Non-Compliant",Assessment!F49="Partially Compliant"),Assessment!B49,"") | C38: =IF(OR(Assessment!F49="Non-Compliant",Assessment!F49="Partially Compliant"),Assessment!C49,"") | D38: =IF(OR(Assessment!F49="Non-Compliant",Assessment!F49="Partially Compliant"),Assessment!D49,"") | E38: =IF(OR(Assessment!F49="Non-Compliant",Assessment!F49="Partially Compliant"),Assessment!E49,"") | F38: =IF(OR(Assessment!F49="Non-Compliant",Assessment!F49="Partially Compliant"),Assessment!F49,"")
A39: =IF(OR(Assessment!F52="Non-Compliant",Assessment!F52="Partially Compliant"),36,"") | B39: =IF(OR(Assessment!F52="Non-Compliant",Assessment!F52="Partially Compliant"),Assessment!B52,"") | C39: =IF(OR(Assessment!F52="Non-Compliant",Assessment!F52="Partially Compliant"),Assessment!C52,"") | D39: =IF(OR(Assessment!F52="Non-Compliant",Assessment!F52="Partially Compliant"),Assessment!D52,"") | E39: =IF(OR(Assessment!F52="Non-Compliant",Assessment!F52="Partially Compliant"),Assessment!E52,"") | F39: =IF(OR(Assessment!F52="Non-Compliant",Assessment!F52="Partially Compliant"),Assessment!F52,"")
A40: =IF(OR(Assessment!F53="Non-Compliant",Assessment!F53="Partially Compliant"),37,"") | B40: =IF(OR(Assessment!F53="Non-Compliant",Assessment!F53="Partially Compliant"),Assessment!B53,"") | C40: =IF(OR(Assessment!F53="Non-Compliant",Assessment!F53="Partially Compliant"),Assessment!C53,"") | D40: =IF(OR(Assessment!F53="Non-Compliant",Assessment!F53="Partially Compliant"),Assessment!D53,"") | E40: =IF(OR(Assessment!F53="Non-Compliant",Assessment!F53="Partially Compliant"),Assessment!E53,"") | F40: =IF(OR(Assessment!F53="Non-Compliant",Assessment!F53="Partially Compliant"),Assessment!F53,"")
...

Sheet Subdomain Summary
A1: NCA ECC-2:2024 — Subdomain Compliance Summary
A2: Ref | B2: Subdomain | C2: Total | D2: Compliant | E2: Partial | F2: Non-Comp. | G2: N/A | H2: Compliance %
A3: CYBERSECURITY GOVERNANCE
A4: 1-1 | B4: Cybersecurity Strategy | C4: 3 | D4: =COUNTIF(Assessment!F6:F8,"Compliant") -> 0 | E4: =COUNTIF(Assessment!F6:F8,"Partially Compliant") -> 0 | F4: =COUNTIF(Assessment!F6:F8,"Non-Compliant") -> 0 | G4: =COUNTIF(Assessment!F6:F8,"Not Applicable") -> 0 | H4: =IF((D4+E4+F4)>0,D4/(D4+E4+F4),0) -> 0
A5: 1-2 | B5: Cybersecurity Management | C5: 3 | D5: =COUNTIF(Assessment!F10:F12,"Compliant") -> 0 | E5: =COUNTIF(Assessment!F10:F12,"Partially Compliant") -> 0 | F5: =COUNTIF(Assessment!F10:F12,"Non-Compliant") -> 0 | G5: =COUNTIF(Assessment!F10:F12,"Not Applicable") -> 0 | H5: =IF((D5+E5+F5)>0,D5/(D5+E5+F5),0) -> 0
A6: 1-3 | B6: Cybersecurity Policies and Procedures | C6: 4 | D6: =COUNTIF(Assessment!F14:F17,"Compliant") -> 0 | E6: =COUNTIF(Assessment!F14:F17,"Partially Compliant") -> 0 | F6: =COUNTIF(Assessment!F14:F17,"Non-Compliant") -> 0 | G6: =COUNTIF(Assessment!F14:F17,"Not Applicable") -> 0 | H6: =IF((D6+E6+F6)>0,D6/(D6+E6+F6),0) -> 0
A7: 1-4 | B7: Cybersecurity Roles and Responsibilities | C7: 2 | D7: =COUNTIF(Assessment!F19:F20,"Compliant") -> 0 | E7: =COUNTIF(Assessment!F19:F20,"Partially Compliant") -> 0 | F7: =COUNTIF(Assessment!F19:F20,"Non-Compliant") -> 0 | G7: =COUNTIF(Assessment!F19:F20,"Not Applicable") -> 0 | H7: =IF((D7+E7+F7)>0,D7/(D7+E7+F7),0) -> 0
A8: 1-5 | B8: Cybersecurity Risk Management | C8: 4 | D8: =COUNTIF(Assessment!F22:F25,"Compliant") -> 0 | E8: =COUNTIF(Assessment!F22:F25,"Partially Compliant") -> 0 | F8: =COUNTIF(Assessment!F22:F25,"Non-Compliant") -> 0 | G8: =COUNTIF(Assessment!F22:F25,"Not Applicable") -> 0 | H8: =IF((D8+E8+F8)>0,D8/(D8+E8+F8),0) -> 0
A9: 1-6 | B9: Cybersecurity in IT Project Management | C9: 4 | D9: =COUNTIF(Assessment!F27:F30,"Compliant") -> 0 | E9: =COUNTIF(Assessment!F27:F30,"Partially Compliant") -> 0 | F9: =COUNTIF(Assessment!F27:F30,"Non-Compliant") -> 0 | G9: =COUNTIF(Assessment!F27:F30,"Not Applicable") -> 0 | H9: =IF((D9+E9+F9)>0,D9/(D9+E9+F9),0) -> 0
A10: 1-7 | B10: Compliance with Standards, Laws & Regulations | C10: 1 | D10: =COUNTIF(Assessment!F32:F32,"Compliant") -> 0 | E10: =COUNTIF(Assessment!F32:F32,"Partially Compliant") -> 0 | F10: =COUNTIF(Assessment!F32:F32,"Non-Compliant") -> 0 | G10: =COUNTIF(Assessment!F32:F32,"Not Applicable") -> 0 | H10: =IF((D10+E10+F10)>0,D10/(D10+E10+F10),0) -> 0
A11: 1-8 | B11: Periodical Review and Audit | C11: 3 | D11: =COUNTIF(Assessment!F34:F36,"Compliant") -> 0 | E11: =COUNTIF(Assessment!F34:F36,"Partially Compliant") -> 0 | F11: =COUNTIF(Assessment!F34:F36,"Non-Compliant") -> 0 | G11: =COUNTIF(Assessment!F34:F36,"Not Applicable") -> 0 | H11: =IF((D11+E11+F11)>0,D11/(D11+E11+F11),0) -> 0
A12: 1-9 | B12: Cybersecurity in Human Resources | C12: 6 | D12: =COUNTIF(Assessment!F38:F43,"Compliant") -> 0 | E12: =COUNTIF(Assessment!F38:F43,"Partially Compliant") -> 0 | F12: =COUNTIF(Assessment!F38:F43,"Non-Compliant") -> 0 | G12: =COUNTIF(Assessment!F38:F43,"Not Applicable") -> 0 | H12: =IF((D12+E12+F12)>0,D12/(D12+E12+F12),0) -> 0
A13: 1-10 | B13: Cybersecurity Awareness & Training | C13: 5 | D13: =COUNTIF(Assessment!F45:F49,"Compliant") -> 0 | E13: =COUNTIF(Assessment!F45:F49,"Partially Compliant") -> 0 | F13: =COUNTIF(Assessment!F45:F49,"Non-Compliant") -> 0 | G13: =COUNTIF(Assessment!F45:F49,"Not Applicable") -> 0 | H13: =IF((D13+E13+F13)>0,D13/(D13+E13+F13),0) -> 0
A14: CYBERSECURITY DEFENSE
A15: 2-1 | B15: Asset Management | C15: 6 | D15: =COUNTIF(Assessment!F52:F57,"Compliant") -> 0 | E15: =COUNTIF(Assessment!F52:F57,"Partially Compliant") -> 0 | F15: =COUNTIF(Assessment!F52:F57,"Non-Compliant") -> 0 | G15: =COUNTIF(Assessment!F52:F57,"Not Applicable") -> 0 | H15: =IF((D15+E15+F15)>0,D15/(D15+E15+F15),0) -> 0
A16: 2-2 | B16: Identity and Access Management | C16: 4 | D16: =COUNTIF(Assessment!F59:F62,"Compliant") -> 0 | E16: =COUNTIF(Assessment!F59:F62,"Partially Compliant") -> 0 | F16: =COUNTIF(Assessment!F59:F62,"Non-Compliant") -> 0 | G16: =COUNTIF(Assessment!F59:F62,"Not Applicable") -> 0 | H16: =IF((D16+E16+F16)>0,D16/(D16+E16+F16),0) -> 0
A17: 2-3 | B17: Information Systems & Facilities Protection | C17: 4 | D17: =COUNTIF(Assessment!F64:F67,"Compliant") -> 0 | E17: =COUNTIF(Assessment!F64:F67,"Partially Compliant") -> 0 | F17: =COUNTIF(Assessment!F64:F67,"Non-Compliant") -> 0 | G17: =COUNTIF(Assessment!F64:F67,"Not Applicable") -> 0 | H17: =IF((D17+E17+F17)>0,D17/(D17+E17+F17),0) -> 0
A18: 2-4 | B18: Email Protection | C18: 4 | D18: =COUNTIF(Assessment!F69:F72,"Compliant") -> 0 | E18: =COUNTIF(Assessment!F69:F72,"Partially Compliant") -> 0 | F18: =COUNTIF(Assessment!F69:F72,"Non-Compliant") -> 0 | G18: =COUNTIF(Assessment!F69:F72,"Not Applicable") -> 0 | H18: =IF((D18+E18+F18)>0,D18/(D18+E18+F18),0) -> 0
A19: 2-5 | B19: Network Security Management | C19: 4 | D19: =COUNTIF(Assessment!F74:F77,"Compliant") -> 0 | E19: =COUNTIF(Assessment!F74:F77,"Partially Compliant") -> 0 | F19: =COUNTIF(Assessment!F74:F77,"Non-Compliant") -> 0 | G19: =COUNTIF(Assessment!F74:F77,"Not Applicable") -> 0 | H19: =IF((D19+E19+F19)>0,D19/(D19+E19+F19),0) -> 0
A20: 2-6 | B20: Mobile Devices Security | C20: 4 | D20: =COUNTIF(Assessment!F79:F82,"Compliant") -> 0 | E20: =COUNTIF(Assessment!F79:F82,"Partially Compliant") -> 0 | F20: =COUNTIF(Assessment!F79:F82,"Non-Compliant") -> 0 | G20: =COUNTIF(Assessment!F79:F82,"Not Applicable") -> 0 | H20: =IF((D20+E20+F20)>0,D20/(D20+E20+F20),0) -> 0
A21: 2-7 | B21: Data and Information Protection | C21: 3 | D21: =COUNTIF(Assessment!F84:F86,"Compliant") -> 0 | E21: =COUNTIF(Assessment!F84:F86,"Partially Compliant") -> 0 | F21: =COUNTIF(Assessment!F84:F86,"Non-Compliant") -> 0 | G21: =COUNTIF(Assessment!F84:F86,"Not Applicable") -> 0 | H21: =IF((D21+E21+F21)>0,D21/(D21+E21+F21),0) -> 0
A22: 2-8 | B22: Cryptography | C22: 4 | D22: =COUNTIF(Assessment!F88:F91,"Compliant") -> 0 | E22: =COUNTIF(Assessment!F88:F91,"Partially Compliant") -> 0 | F22: =COUNTIF(Assessment!F88:F91,"Non-Compliant") -> 0 | G22: =COUNTIF(Assessment!F88:F91,"Not Applicable") -> 0 | H22: =IF((D22+E22+F22)>0,D22/(D22+E22+F22),0) -> 0
A23: 2-9 | B23: Backup and Recovery Management | C23: 4 | D23: =COUNTIF(Assessment!F93:F96,"Compliant") -> 0 | E23: =COUNTIF(Assessment!F93:F96,"Partially Compliant") -> 0 | F23: =COUNTIF(Assessment!F93:F96,"Non-Compliant") -> 0 | G23: =COUNTIF(Assessment!F93:F96,"Not Applicable") -> 0 | H23: =IF((D23+E23+F23)>0,D23/(D23+E23+F23),0) -> 0
A24: 2-10 | B24: Vulnerability Management | C24: 4 | D24: =COUNTIF(Assessment!F98:F101,"Compliant") -> 0 | E24: =COUNTIF(Assessment!F98:F101,"Partially Compliant") -> 0 | F24: =COUNTIF(Assessment!F98:F101,"Non-Compliant") -> 0 | G24: =COUNTIF(Assessment!F98:F101,"Not Applicable") -> 0 | H24: =IF((D24+E24+F24)>0,D24/(D24+E24+F24),0) -> 0
A25: 2-11 | B25: Penetration Testing | C25: 4 | D25: =COUNTIF(Assessment!F103:F106,"Compliant") -> 0 | E25: =COUNTIF(Assessment!F103:F106,"Partially Compliant") -> 0 | F25: =COUNTIF(Assessment!F103:F106,"Non-Compliant") -> 0 | G25: =COUNTIF(Assessment!F103:F106,"Not Applicable") -> 0 | H25: =IF((D25+E25+F25)>0,D25/(D25+E25+F25),0) -> 0
A26: 2-12 | B26: Event Logs and Monitoring | C26: 4 | D26: =COUNTIF(Assessment!F108:F111,"Compliant") -> 0 | E26: =COUNTIF(Assessment!F108:F111,"Partially Compliant") -> 0 | F26: =COUNTIF(Assessment!F108:F111,"Non-Compliant") -> 0 | G26: =COUNTIF(Assessment!F108:F111,"Not Applicable") -> 0 | H26: =IF((D26+E26+F26)>0,D26/(D26+E26+F26),0) -> 0
A27: 2-13 | B27: Incident and Threat Management | C27: 4 | D27: =COUNTIF(Assessment!F113:F116,"Compliant") -> 0 | E27: =COUNTIF(Assessment!F113:F116,"Partially Compliant") -> 0 | F27: =COUNTIF(Assessment!F113:F116,"Non-Compliant") -> 0 | G27: =COUNTIF(Assessment!F113:F116,"Not Applicable") -> 0 | H27: =IF((D27+E27+F27)>0,D27/(D27+E27+F27),0) -> 0
A28: 2-14 | B28: Physical Security | C28: 4 | D28: =COUNTIF(Assessment!F118:F121,"Compliant") -> 0 | E28: =COUNTIF(Assessment!F118:F121,"Partially Compliant") -> 0 | F28: =COUNTIF(Assessment!F118:F121,"Non-Compliant") -> 0 | G28: =COUNTIF(Assessment!F118:F121,"Not Applicable") -> 0 | H28: =IF((D28+E28+F28)>0,D28/(D28+E28+F28),0) -> 0
A29: 2-15 | B29: Web Application Security | C29: 4 | D29: =COUNTIF(Assessment!F123:F126,"Compliant") -> 0 | E29: =COUNTIF(Assessment!F123:F126,"Partially Compliant") -> 0 | F29: =COUNTIF(Assessment!F123:F126,"Non-Compliant") -> 0 | G29: =COUNTIF(Assessment!F123:F126,"Not Applicable") -> 0 | H29: =IF((D29+E29+F29)>0,D29/(D29+E29+F29),0) -> 0
A30: CYBERSECURITY RESILIENCE
A31: 3-1 | B31: BCM Cybersecurity Resilience | C31: 4 | D31: =COUNTIF(Assessment!F129:F132,"Compliant") -> 0 | E31: =COUNTIF(Assessment!F129:F132,"Partially Compliant") -> 0 | F31: =COUNTIF(Assessment!F129:F132,"Non-Compliant") -> 0 | G31: =COUNTIF(Assessment!F129:F132,"Not Applicable") -> 0 | H31: =IF((D31+E31+F31)>0,D31/(D31+E31+F31),0) -> 0
A32: THIRD-PARTY & CLOUD CYBERSECURITY
A33: 4-1 | B33: Third-Party Cybersecurity | C33: 4 | D33: =COUNTIF(Assessment!F135:F138,"Compliant") -> 0 | E33: =COUNTIF(Assessment!F135:F138,"Partially Compliant") -> 0 | F33: =COUNTIF(Assessment!F135:F138,"Non-Compliant") -> 0 | G33: =COUNTIF(Assessment!F135:F138,"Not Applicable") -> 0 | H33: =IF((D33+E33+F33)>0,D33/(D33+E33+F33),0) -> 0
A34: 4-2 | B34: Cloud Computing & Hosting Cybersecurity | C34: 4 | D34: =COUNTIF(Assessment!F140:F143,"Compliant") -> 0 | E34: =COUNTIF(Assessment!F140:F143,"Partially Compliant") -> 0 | F34: =COUNTIF(Assessment!F140:F143,"Non-Compliant") -> 0 | G34: =COUNTIF(Assessment!F140:F143,"Not Applicable") -> 0 | H34: =IF((D34+E34+F34)>0,D34/(D34+E34+F34),0) -> 0

Sheet VBA Macro Instructions
B2: HOW TO ENABLE INTERACTIVE DIMMING (VBA Macro)
B5: This workbook includes a VBA macro that automatically dims/highlights rows based on status selection.
B6: Since .xlsx files cannot contain macros, follow these steps to enable the feature:
B8: STEP 1: Save this file as .xlsm (Excel Macro-Enabled Workbook)
B9: - File > Save As > Change type to 'Excel Macro-Enabled Workbook (.xlsm)'
B11: STEP 2: Open the VBA Editor
B12: - Press Alt+F11 (or Developer > Visual Basic)
B14: STEP 3: Find the Assessment sheet module
B15: - In the Project Explorer (left panel), expand your workbook
B16: - Double-click on the 'Assessment' sheet (under Microsoft Excel Objects)
B18: STEP 4: Paste the VBA code below into the code window
B19: - Copy everything between the === markers below and paste it in the editor
... B107: End Sub
